Workbook

Sheet New Signups
P1: Wave 1 | AA1: Wave 2 | AO1: Wave 3
B2: PID | C2: Record ID | D2: First Name | E2: Last Name | F2: Gender | G2: Age | H2: Parent Name | I2: Guardian/Older Cohort Phone | J2: Child Phone | L2: Recruitment Source | M2: LONG TERM NOTES | N2: Next Contact Step | O2: Next date to contact | P2: Wave 1 initial contact | Q2: Schedule Screener | R2: Screener | S2: Schedule V1 | T2: v1 reminder | U2: Check for v1 completion | V2: Schedule V2 | W2: 4 days before v2 reminder | X2: 1 day before v2 reminder | Y2: Check for v2 completion | Z2: Wave 2 start month | AA2: Wave 2 initial contact | AB2: Schedule Screener | AC2: Screener | AD2: Schedule V1 | AE2: 3 day before V1 reminder | AF2: v1 reminder | AG2: Check for v1 completion | AH2: Check at Home survey completion | AI2: Schedule V2 | AJ2: 4 days before v2 reminder | AK2: 1 day before v2 reminder | AL2: Check for v2 completion | AM2: Travel Payments (send text and set auto email) | AN2: Wave 3 start month | AO2: Wave 3 initial contact | AP2: Schedule Screener | AQ2: Screener | AR2: Schedule V1 | AS2: v1 reminder | AT2: Check for v1 completion | AU2: V1 Payment | AV2: Schedule V2 | AW2: 4 days before v2 reminder | AX2: 1 day before v2 reminder | AY2: Check for v2 completion | AZ2: Travel Payments (send text and set auto email)
B3: {=ifna(iferror(xlookup(C:C,'1000'!A:A,'1000'!D:D),iferror(xlookup(C:C,'2000'!A:A,'2000'!D:D),xlookup(C:C,'3000'!A:A,'3000'!D:D))),"-")} -> 1114 | C3: 1609 | D3: nia | E3: brown | F3: Female (1) | G3: 12 | H3: Regina brown | I3: (215) 251-7688 | J3: (215) 551-7688 | K3: CLINICONTACT | L3: CLINICONTACT | N3: dont contact until avi clears - schedule screener - If no response, x. - AD 5/5/2026 | O3: 46167 | P3: TP | Q3: DZ | R3: MV | S3: MV | T3: MV | U3: DZ | V3: DZ | W3: MV | X3: MV | Y3: MV | Z3: {=IFERROR(xlookup(C:C,'Follow up.1'!A:A,'Follow up.1'!AF:AF),"-")} -> 05/26 | AA3: AC | AN3: {=IF(LEFT(B3,1)="3","x",IFNA(LET(raw,XLOOKUP(C3,'Follow up.2'!B:B,'Follow up.2'!AF:AF),IF(OR(raw="",raw=0),"-",TEXT(MIN(--raw,DATE(2027,6,1)),"mm/yyyy"))),"-"))} -> -
B4: {=ifna(iferror(xlookup(C:C,'1000'!A:A,'1000'!D:D),iferror(xlookup(C:C,'2000'!A:A,'2000'!D:D),xlookup(C:C,'3000'!A:A,'3000'!D:D))),"-")} -> 1124 | C4: 1703 | D4: Layala | E4: Dachs | F4: F | G4: 12 | H4: Avi Dachs | I4: (267) 285-3947 | L4: Avi's sister | M4: Text "Avi" to schedule | N4: w3 intial contact (ANDY SET DATE) | O4: 46167 | P4: AD | Q4: AD | R4: AD | S4: AD | T4: AD | U4: AD | V4: MV | W4: MV | X4: MV | Y4: CP | Z4: {=IFERROR(xlookup(C:C,'Follow up.1'!A:A,'Follow up.1'!AF:AF),"-")} -> 05/26 | AA4: AC | AB4: AD | AC4: AD | AD4: AD | AE4: X | AF4: X | AG4: X | AH4: KD | AI4: AD | AN4: {=IF(LEFT(B4,1)="3","x",IFNA(LET(raw,XLOOKUP(C4,'Follow up.2'!B:B,'Follow up.2'!AF:AF),IF(OR(raw="",raw=0),"-",TEXT(MIN(--raw,DATE(2027,6,1)),"mm/yyyy"))),"-"))} -> -
B5: {=ifna(iferror(xlookup(C:C,'1000'!A:A,'1000'!D:D),iferror(xlookup(C:C,'2000'!A:A,'2000'!D:D),xlookup(C:C,'3000'!A:A,'3000'!D:D))),"-")} -> 2098 | C5: 1859 | D5: Niang | E5: Dim Mang | F5: Female (1) | G5: 14 | H5: manu | I5: (260)702-5469 | J5: (215) 433-2036 | K5: niang.mang210@gmail.com | L5: CLINICONTACT | M5: her receipts got switched v2 reciept is actually v1 | N5: W3 initial contact (ANDY SET DATE) | O5: 46167 | P5: CP | Q5: MV | R5: MV | S5: MV | T5: TP | U5: MV | V5: MV | W5: IA | X5: CP | Y5: MV | Z5: {=IFERROR(xlookup(C:C,'Follow up.1'!A:A,'Follow up.1'!AF:AF),"-")} -> 05/26 | AA5: AC | AB5: AC | AC5: AC | AD5: AC | AE5: AC | AF5: AC | AG5: AC | AI5: AD | AJ5: AD | AL5: AC | AM5: AC | AN5: {=IF(LEFT(B5,1)="3","x",IFNA(LET(raw,XLOOKUP(C5,'Follow up.2'!B:B,'Follow up.2'!AF:AF),IF(OR(raw="",raw=0),"-",TEXT(MIN(--raw,DATE(2027,6,1)),"mm/yyyy"))),"-"))} -> -
B6: {=ifna(iferror(xlookup(C:C,'1000'!A:A,'1000'!D:D),iferror(xlookup(C:C,'2000'!A:A,'2000'!D:D),xlookup(C:C,'3000'!A:A,'3000'!D:D))),"-")} -> 2106 | C6: 1647 | D6: Ian | E6: Navarro | F6: Male (2) | G6: 15 | H6: Yalitza Perez | I6: (267) 319-4267 | J6: (267) 581-2238 | K6: CLINICONTACT | L6: CLINICONTACT | N6: Travel payments | O6: 46167 | P6: DZ | Q6: DZ | R6: BS | S6: BS | T6: MV | U6: MV | V6: MV | W6: MV | X6: DZ | Y6: DZ | Z6: {=IFERROR(xlookup(C:C,'Follow up.1'!A:A,'Follow up.1'!AF:AF),"-")} -> 05/26 | AA6: AC | AD6: AD | AE6: AN | AF6: AN | AG6: AP | AJ6: AC | AK6: AN | AL6: AP | AN6: {=IF(LEFT(B6,1)="3","x",IFNA(LET(raw,XLOOKUP(C6,'Follow up.2'!B:B,'Follow up.2'!AF:AF),IF(OR(raw="",raw=0),"-",TEXT(MIN(--raw,DATE(2027,6,1)),"mm/yyyy"))),"-"))} -> 06/2027
B7: {=ifna(iferror(xlookup(C:C,'1000'!A:A,'1000'!D:D),iferror(xlookup(C:C,'2000'!A:A,'2000'!D:D),xlookup(C:C,'3000'!A:A,'3000'!D:D))),"-")} -> 1117 | C7: 1614 | D7: Liam | E7: Galvez | F7: male | G7: 12 | H7: Dana Newsome | I7: (215) 510-6544 | J7: (215) 510-6544 | K7: CLINICONTACT | L7: CLINICONTACT | M7: saw they were called | N7: wait to contact again until Avi clears them (v2) | O7: 46171 | P7: TP | Q7: DZ | R7: DZ | S7: DZ | T7: DZ | U7: BS | V7: KL | W7: MV | X7: MV | Y7: AK | Z7: {=IFERROR(xlookup(C:C,'Follow up.1'!A:A,'Follow up.1'!AF:AF),"-")} -> 04/26 | AA7: BH | AB7: BH | AC7: AC | AE7: CP | AF7: MV | AG7: RY | AN7: {=IF(LEFT(B7,1)="3","x",IFNA(LET(raw,XLOOKUP(C7,'Follow up.2'!B:B,'Follow up.2'!AF:AF),IF(OR(raw="",raw=0),"-",TEXT(MIN(--raw,DATE(2027,6,1)),"mm/yyyy"))),"-"))} -> -
B8: 2112 | C8: 1830 | D8: Kristian | E8: Kilgore | F8: Male (2) | G8: 15 | H8: Dinah Jiles | I8: (267) 776-3612 | J8: (267) 579-8298 | L8: A family member who was also signing up | M8: needs to reschedule v1 (canceled x1 - add reason here) | N8: wait to contact again until Avi clears them (cut?) | O8: 46171 | P8: MV | Q8: MV | R8: MV | S8: MV | T8: MV | U8: MV | V8: MV | W8: AK | X8: AK | Y8: MV | Z8: {=IFERROR(xlookup(C:C,'Follow up.1'!A:A,'Follow up.1'!AF:AF),"-")} -> 04/26 | AA8: BH | AF8: CP | AN8: {=IF(LEFT(B8,1)="3","x",IFNA(LET(raw,XLOOKUP(C8,'Follow up.2'!B:B,'Follow up.2'!AF:AF),IF(OR(raw="",raw=0),"-",TEXT(MIN(--raw,DATE(2027,6,1)),"mm/yyyy"))),"-"))} -> -
B9: {=ifna(iferror(xlookup(C:C,'1000'!A:A,'1000'!D:D),iferror(xlookup(C:C,'2000'!A:A,'2000'!D:D),xlookup(C:C,'3000'!A:A,'3000'!D:D))),"-")} -> 1070 | C9: 1356 | D9: Chaniel | E9: Rackley | F9: male | G9: 9 | H9: Kimberly Rackley | I9: (864) 404-6545 | K9: Clinicontact | L9: Clinicontact | M9: 1172/1171 sibling | N9: dont contact until avi clears- Schedule V1 | O9: 46174 | P9: DZ | Q9: DZ | R9: DZ | S9: DZ | T9: AD | U9: AM | V9: DZ | W9: AD | X9: AD | Y9: DZ | Z9: {=IFERROR(xlookup(C:C,'Follow up.1'!A:A,'Follow up.1'!AF:AF),"-")} -> 12/25 | AA9: KL | AB9: - | AC9: IA | AD9: IA | AN9: {=IF(LEFT(B9,1)="3","x",IFNA(LET(raw,XLOOKUP(C9,'Follow up.2'!B:B,'Follow up.2'!AF:AF),IF(OR(raw="",raw=0),"-",TEXT(MIN(--raw,DATE(2027,6,1)),"mm/yyyy"))),"-"))} -> -
B10: {=ifna(iferror(xlookup(C:C,'1000'!A:A,'1000'!D:D),iferror(xlookup(C:C,'2000'!A:A,'2000'!D:D),xlookup(C:C,'3000'!A:A,'3000'!D:D))),"-")} -> 1058 | C10: 1129 | D10: Hendrix | E10: Carpenter | F10: Male (2) | G10: 10 | H10: Ashley Carpenter | I10: (609) 929-2222 | K10: CLINICONTACT | L10: CLINICONTACT | M10: Reach out in summer b/c they live in NJ and do sports | N10: dont contact until avi clears- screener | O10: 46174 | P10: DH | Q10: AD | R10: AD | S10: AD | T10: DZ | U10: BS | V10: DZ | W10: BS | X10: BS | Y10: AM | Z10: {=IFERROR(xlookup(C:C,'Follow up.1'!A:A,'Follow up.1'!AF:AF),"-")} -> 10/25 | AA10: AD | AB10: KL | AC10: CP | AN10: {=IF(LEFT(B10,1)="3","x",IFNA(LET(raw,XLOOKUP(C10,'Follow up.2'!B:B,'Follow up.2'!AF:AF),IF(OR(raw="",raw=0),"-",TEXT(MIN(--raw,DATE(2027,6,1)),"mm/yyyy"))),"-"))} -> -
B11: {=ifna(iferror(xlookup(C:C,'1000'!A:A,'1000'!D:D),iferror(xlookup(C:C,'2000'!A:A,'2000'!D:D),xlookup(C:C,'3000'!A:A,'3000'!D:D))),"-")} -> 1007 | C11: 127 | D11: Morgan | E11: Weaver | F11: M | G11: 9 | H11: Jessica Weaver | I11: (267) 928-7334 | N11: w3 schedule screener (cut?) | O11: 46176 | P11: DZ | Q11: BS | R11: BS | S11: BS | T11: BS | U11: BS | V11: MV | W11: DZ | X11: DZ | Y11: DZ | Z11: {=IFERROR(xlookup(C:C,'Follow up.1'!A:A,'Follow up.1'!AF:AF),"-")} -> 10/24 | AA11: AM | AB11: AD | AC11: AD | AD11: AD | AF11: DZ | AG11: DZ | AI11: DZ | AJ11: DZ | AK11: KL | AL11: CP | AM11: n/a | AN11: {=IF(LEFT(B11,1)="3","x",IFNA(LET(raw,XLOOKUP(C11,'Follow up.2'!B:B,'Follow up.2'!AF:AF),IF(OR(raw="",raw=0),"-",TEXT(MIN(--raw,DATE(2027,6,1)),"mm/yyyy"))),"-"))} -> 06/2026 | AO11: AN
B12: {=ifna(iferror(xlookup(C:C,'1000'!A:A,'1000'!D:D),iferror(xlookup(C:C,'2000'!A:A,'2000'!D:D),xlookup(C:C,'3000'!A:A,'3000'!D:D))),"-")} -> 1064 | C12: 1208 | D12: Isaiah | E12: Watts | F12: Male | G12: 8 | H12: Catrisha Watts | I12: (757) 651-6569 | K12: CLINICONTACT | L12: CLINICONTACT | N12: wait to schedule v1 until Avi clears them | O12: 46181 | P12: DZ | Q12: DZ | R12: DZ | S12: DZ | T12: DZ | U12: DZ | V12: DZ | W12: KL | X12: KL | Y12: MV | Z12: {=IFERROR(xlookup(C:C,'Follow up.1'!A:A,'Follow up.1'!AF:AF),"-")} -> 04/26 | AA12: AC | AB12: MS | AC12: MS | AD12: MS | AN12: {=IF(LEFT(B12,1)="3","x",IFNA(LET(raw,XLOOKUP(C12,'Follow up.2'!B:B,'Follow up.2'!AF:AF),IF(OR(raw="",raw=0),"-",TEXT(MIN(--raw,DATE(2027,6,1)),"mm/yyyy"))),"-"))} -> -
B13: {=ifna(iferror(xlookup(C:C,'1000'!A:A,'1000'!D:D),iferror(xlookup(C:C,'2000'!A:A,'2000'!D:D),xlookup(C:C,'3000'!A:A,'3000'!D:D))),"-")} -> 1063 | C13: 1207 | D13: Shiloh | E13: Watts | F13: Male | G13: 11 | H13: Catrisha Watts | I13: (757) 651-6569 | K13: CLINICONTACT | L13: CLINICONTACT | N13: wait to schedule v1 until Avi clears them | O13: 46181 | P13: DZ | Q13: DZ | R13: DZ | S13: DZ | T13: DZ | U13: DZ | V13: DZ | W13: KL | X13: KL | Y13: MV | Z13: {=IFERROR(xlookup(C:C,'Follow up.1'!A:A,'Follow up.1'!AF:AF),"-")} -> 04/26 | AA13: AC | AB13: MS | AC13: MS | AD13: MS | AN13: {=IF(LEFT(B13,1)="3","x",IFNA(LET(raw,XLOOKUP(C13,'Follow up.2'!B:B,'Follow up.2'!AF:AF),IF(OR(raw="",raw=0),"-",TEXT(MIN(--raw,DATE(2027,6,1)),"mm/yyyy"))),"-"))} -> -
B14: {=ifna(iferror(xlookup(C:C,'1000'!A:A,'1000'!D:D),iferror(xlookup(C:C,'2000'!A:A,'2000'!D:D),xlookup(C:C,'3000'!A:A,'3000'!D:D))),"-")} -> 2051 | C14: 1076 | D14: Judah | E14: Watts | F14: M | G14: M15 | H14: Catrisha Watts | I14: (757) 651-6569 | J14: (757) 470-6417 | K14: CLINICONTACT | L14: CLINICONTACT | M14: 1194 sibling | N14: Wait to schedule v2 until Avi clears them | O14: 46181 | P14: BS | Q14: DZ | R14: DZ | S14: DZ | T14: AD | U14: DZ | V14: DZ | W14: DZ | X14: DZ | Y14: DZ | Z14: {=IFERROR(xlookup(C:C,'Follow up.1'!A:A,'Follow up.1'!AF:AF),"-")} -> 10/25 | AA14: AK | AB14: AM | AC14: SM | AD14: AD | AF14: AC | AG14: AK | AI14: BH, CP | AJ14: AD,AD | AK14: AC, RY | AN14: {=IF(LEFT(B14,1)="3","x",IFNA(LET(raw,XLOOKUP(C14,'Follow up.2'!B:B,'Follow up.2'!AF:AF),IF(OR(raw="",raw=0),"-",TEXT(MIN(--raw,DATE(2027,6,1)),"mm/yyyy"))),"-"))} -> -
B15: {=ifna(iferror(xlookup(C:C,'1000'!A:A,'1000'!D:D),iferror(xlookup(C:C,'2000'!A:A,'2000'!D:D),xlookup(C:C,'3000'!A:A,'3000'!D:D))),"-")} -> 2005 | C15: 13 | D15: Elliott | E15: Clair | H15: Orli Gal | I15: (267) 265-8456 | J15: 267-909-6200 | M15: waiting for flights to get scheduled | N15: dont contact until avi clears- Schedule v1/ child living in west coast | O15: 46181 | P15: DZ | Q15: DZ | R15: DZ | S15: DZ | T15: DZ | U15: DZ | V15: DZ | W15: DZ | X15: DZ | Y15: DZ | Z15: {=IFERROR(xlookup(C:C,'Follow up.1'!A:A,'Follow up.1'!AF:AF),"-")} -> 10/24 | AA15: MV | AB15: MV | AC15: MV | AD15: MV | AF15: MV | AG15: AK | AI15: MV | AJ15: DZ | AK15: DZ | AL15: DZ | AM15: n/a | AN15: {=IF(LEFT(B15,1)="3","x",IFNA(LET(raw,XLOOKUP(C15,'Follow up.2'!B:B,'Follow up.2'!AF:AF),IF(OR(raw="",raw=0),"-",TEXT(MIN(--raw,DATE(2027,6,1)),"mm/yyyy"))),"-"))} -> 03/2026 | AO15: CP
B16: {=ifna(iferror(xlookup(C:C,'1000'!A:A,'1000'!D:D),iferror(xlookup(C:C,'2000'!A:A,'2000'!D:D),xlookup(C:C,'3000'!A:A,'3000'!D:D))),"-")} -> 1127 | C16: 1754 | D16: Noelle | E16: Ferguson | F16: Female (1) | G16: 12 | H16: Christina Danielle Turner | I16: (267) 648-3537 | J16: (267) 438-9939 | L16: CLINICONTACT | N16: reschedule w2 Screener - called no answer 6/15/26 | O16: 46195 | P16: MV | Q16: KL | R16: KL | S16: KL | T16: KL | U16: MV | V16: KL | W16: MV | X16: CP | Y16: MV | Z16: {=IFERROR(xlookup(C:C,'Follow up.1'!A:A,'Follow up.1'!AF:AF),"-")} -> 05/26 | AA16: AC | AB16: AC | AJ16: AC | AN16: {=IF(LEFT(B16,1)="3","x",IFNA(LET(raw,XLOOKUP(C16,'Follow up.2'!B:B,'Follow up.2'!AF:AF),IF(OR(raw="",raw=0),"-",TEXT(MIN(--raw,DATE(2027,6,1)),"mm/yyyy"))),"-"))} -> -
B17: {=ifna(iferror(xlookup(C:C,'1000'!A:A,'1000'!D:D),iferror(xlookup(C:C,'2000'!A:A,'2000'!D:D),xlookup(C:C,'3000'!A:A,'3000'!D:D))),"-")} -> 2055 | C17: 1088 | D17: Gilpatrick | E17: Ben-Yaacov | F17: M | G17: M14 | H17: Kate Dugan | I17: (609) 744-1033 | J17: (215) 514-0531 | K17: (Awbury Arboretum summer camp) | L17: (Awbury Arboretum summer camp) | N17: w3 intital | O17: 46545 | P17: AM | Q17: DZ | R17: DZ | S17: DZ | T17: BS | U17: BS | V17: KL | W17: DZ | X17: DZ | Y17: MV | Z17: {=IFERROR(xlookup(C:C,'Follow up.1'!A:A,'Follow up.1'!AF:AF),"-")} -> 02/26 | AA17: MV | AB17: - | AC17: BH | AD17: BH | AF17: AC | AG17: RY | AI17: AP | AJ17: AC | AK17: AN | AL17: AP | AN17: {=IF(LEFT(B17,1)="3","x",IFNA(LET(raw,XLOOKUP(C17,'Follow up.2'!B:B,'Follow up.2'!AF:AF),IF(OR(raw="",raw=0),"-",TEXT(MIN(--raw,DATE(2027,6,1)),"mm/yyyy"))),"-"))} -> 06/2027
B18: {=ifna(iferror(xlookup(C:C,'1000'!A:A,'1000'!D:D),iferror(xlookup(C:C,'2000'!A:A,'2000'!D:D),xlookup(C:C,'3000'!A:A,'3000'!D:D))),"-")} -> 1105 | C18: 1574 | D18: Tyler | E18: Romanelli | F18: Male | G18: 9 | H18: Saki Sono Romanelli | I18: (203) 464-1205 | J18: (508) 808-2411 | K18: Mr. Naoya Tani | L18: Mr. Naoya Tani | M18: Maybe don't schedule v2, did not want to do v1 and notes show he quit v2 halfway through pat last year | N18: v2 schedule | O18: 46196 | P18: MV | Q18: AM | R18: AM | S18: AM | T18: DZ | U18: SB | V18: SB | W18: TP | X18: TP | Y18: MV | Z18: {=IFERROR(xlookup(C:C,'Follow up.1'!A:A,'Follow up.1'!AF:AF),"-")} -> 05/26 | AA18: AC | AD18: AC | AE18: AC | AF18: AP | AG18: RY | AN18: {=IF(LEFT(B18,1)="3","x",IFNA(LET(raw,XLOOKUP(C18,'Follow up.2'!B:B,'Follow up.2'!AF:AF),IF(OR(raw="",raw=0),"-",TEXT(MIN(--raw,DATE(2027,6,1)),"mm/yyyy"))),"-"))} -> -
B19: {=ifna(iferror(xlookup(C:C,'1000'!A:A,'1000'!D:D),iferror(xlookup(C:C,'2000'!A:A,'2000'!D:D),xlookup(C:C,'3000'!A:A,'3000'!D:D))),"-")} -> 2100 | C19: 1575 | D19: Allisa | E19: Romanelli | F19: Female | G19: 15 | H19: Saki Sono Romanelli | I19: (203) 464-1205 | J19: (508) 808-2411 | K19: Mr. Naoya Tani | L19: Mr. Naoya Tani | N19: v2 schedule | O19: 46196 | P19: MV | Q19: AM | R19: AM | S19: AM | T19: DZ | U19: SB | V19: SB | W19: TP | X19: TP | Y19: MV | Z19: {=IFERROR(xlookup(C:C,'Follow up.1'!A:A,'Follow up.1'!AF:AF),"-")} -> - | AA19: AC | AD19: AC | AE19: AC | AF19: AP | AG19: RY | AN19: {=IF(LEFT(B19,1)="3","x",IFNA(LET(raw,XLOOKUP(C19,'Follow up.2'!B:B,'Follow up.2'!AF:AF),IF(OR(raw="",raw=0),"-",TEXT(MIN(--raw,DATE(2027,6,1)),"mm/yyyy"))),"-"))} -> -
B20: {=ifna(iferror(xlookup(C:C,'1000'!A:A,'1000'!D:D),iferror(xlookup(C:C,'2000'!A:A,'2000'!D:D),xlookup(C:C,'3000'!A:A,'3000'!D:D))),"-")} -> 2087 | C20: 1531 | D20: Layla | E20: Young | F20: Female | G20: 12 | H20: Sheliah Yuille | I20: (215) 201-8965 | K20: parent | L20: parent | N20: v2 schedule | O20: 46196 | P20: AM | Q20: DZ | R20: DZ | S20: DZ | T20: AM | U20: AM | V20: TP | W20: MV | X20: AM | Y20: AM | Z20: {=IFERROR(xlookup(C:C,'Follow up.1'!A:A,'Follow up.1'!AF:AF),"-")} -> 05/26 | AA20: AC | AB20: AD | AC20: AD | AD20: AP | AE20: AN | AF20: RY | AG20: RY | AN20: {=IF(LEFT(B20,1)="3","x",IFNA(LET(raw,XLOOKUP(C20,'Follow up.2'!B:B,'Follow up.2'!AF:AF),IF(OR(raw="",raw=0),"-",TEXT(MIN(--raw,DATE(2027,6,1)),"mm/yyyy"))),"-"))} -> -
B21: {=ifna(iferror(xlookup(C:C,'1000'!A:A,'1000'!D:D),iferror(xlookup(C:C,'2000'!A:A,'2000'!D:D),xlookup(C:C,'3000'!A:A,'3000'!D:D))),"-")} -> 2113 | C21: 1810 | D21: Chelsea | E21: George | F21: Female (1) | G21: 16 | H21: Chelsea G | I21: (267) 366-7176 | J21: (610) 803-6519 | L21: CLINICONTACT | M21: try and finish w2 no w3 | N21: reschedule v1/ghosting/ if no response cut them | O21: 46196 | P21: MV | Q21: MV | R21: MV | S21: MV | T21: KL | U21: MV | V21: KL | W21: AK | X21: AK | Y21: MV | Z21: {=IFERROR(xlookup(C:C,'Follow up.1'!A:A,'Follow up.1'!AF:AF),"-")} -> 05/26 | AA21: AC | AB21: AD | AC21: AD | AD21: AC | AE21: RY | AN21: {=IF(LEFT(B21,1)="3","x",IFNA(LET(raw,XLOOKUP(C21,'Follow up.2'!B:B,'Follow up.2'!AF:AF),IF(OR(raw="",raw=0),"-",TEXT(MIN(--raw,DATE(2027,6,1)),"mm/yyyy"))),"-"))} -> -
B22: {=ifna(iferror(xlookup(C:C,'1000'!A:A,'1000'!D:D),iferror(xlookup(C:C,'2000'!A:A,'2000'!D:D),xlookup(C:C,'3000'!A:A,'3000'!D:D))),"-")} -> 1128 | C22: 1806 | D22: Haylee | E22: Jones | F22: Female (1) | G22: 10 | H22: Joanne Carrasquillo | I22: (267) 761-6115 | J22: (484) 788-7075 | L22: CLINICONTACT | N22: v2 reminder 1 day | O22: 46196 | P22: MV | Q22: KL | R22: KL | S22: KL | T22: MV | U22: KL | V22: KL | W22: MV | X22: MV | Y22: KL | Z22: {=IFERROR(xlookup(C:C,'Follow up.1'!A:A,'Follow up.1'!AF:AF),"-")} -> 05/26 | AA22: AC | AB22: AD | AC22: MS | AD22: MS | AE22: AC | AF22: AC | AG22: AD | AH22: AD | AJ22: AP | AN22: {=IF(LEFT(B22,1)="3","x",IFNA(LET(raw,XLOOKUP(C22,'Follow up.2'!B:B,'Follow up.2'!AF:AF),IF(OR(raw="",raw=0),"-",TEXT(MIN(--raw,DATE(2027,6,1)),"mm/yyyy"))),"-"))} -> -
B23: {=ifna(iferror(xlookup(C:C,'1000'!A:A,'1000'!D:D),iferror(xlookup(C:C,'2000'!A:A,'2000'!D:D),xlookup(C:C,'3000'!A:A,'3000'!D:D))),"-")} -> 1089 | C23: 1538 | D23: Sebastien | E23: Mason | F23: Male | G23: 10 | H23: Emily Mason | I23: (917) 698-9694 | K23: email | L23: email | M23: siblings with 2086 no w3 | N23: Follow-Up About V1 Scheduling | O23: 46196 | P23: MV | Q23: DZ | R23: DZ | S23: DZ | T23: DZ | U23: TP | V23: KL | W23: DZ | X23: DZ | Y23: DZ | Z23: {=IFERROR(xlookup(C:C,'Follow up.1'!A:A,'Follow up.1'!AF:AF),"-")} -> 04/26 | AA23: BH | AB23: MS | AC23: EB | AD23: EB | AN23: {=IF(LEFT(B23,1)="3","x",IFNA(LET(raw,XLOOKUP(C23,'Follow up.2'!B:B,'Follow up.2'!AF:AF),IF(OR(raw="",raw=0),"-",TEXT(MIN(--raw,DATE(2027,6,1)),"mm/yyyy"))),"-"))} -> -
B24: {=ifna(iferror(xlookup(C:C,'1000'!A:A,'1000'!D:D),iferror(xlookup(C:C,'2000'!A:A,'2000'!D:D),xlookup(C:C,'3000'!A:A,'3000'!D:D))),"-")} -> 2086 | C24: 1537 | D24: Oliver | E24: Mason | F24: Male | G24: 14 | H24: Emily Mason | I24: (917) 698-9694 | J24: (856) 631-4323 | K24: email | L24: email | M24: siblings with 1089 | N24: Follow-Up About V1 Scheduling | O24: 46196 | P24: MV | Q24: DZ | R24: DZ | S24: DZ | T24: DZ | U24: DZ | V24: DZ | W24: AD | X24: AD | Y24: DZ | Z24: {=IFERROR(xlookup(C:C,'Follow up.1'!A:A,'Follow up.1'!AF:AF),"-")} -> 04/26 | AA24: BH | AB24: MS | AC24: EB | AD24: EB | AN24: {=IF(LEFT(B24,1)="3","x",IFNA(LET(raw,XLOOKUP(C24,'Follow up.2'!B:B,'Follow up.2'!AF:AF),IF(OR(raw="",raw=0),"-",TEXT(MIN(--raw,DATE(2027,6,1)),"mm/yyyy"))),"-"))} -> -
B25: {=ifna(iferror(xlookup(C:C,'1000'!A:A,'1000'!D:D),iferror(xlookup(C:C,'2000'!A:A,'2000'!D:D),xlookup(C:C,'3000'!A:A,'3000'!D:D))),"-")} -> 1113 | C25: 1468 | D25: Lincoln she/her | E25: Monahan | F25: Female | G25: 7 | H25: Megan Monahan | I25: (610) 763-6696 | K25: Email | L25: Email | M25: Sibling is 1005 - delayed w2 contact date by month so siblings can come together- already completed screener? | N25: schedule WAVE2 v1- july date she wants | O25: 46196 | P25: MV | Q25: MV | R25: DZ | S25: DZ | T25: AD | U25: DZ | V25: DZ | W25: DZ | X25: DZ | Y25: DZ | Z25: {=IFERROR(xlookup(C:C,'Follow up.1'!A:A,'Follow up.1'!AF:AF),"-")} -> - | AA25: EB | AB25: EB | AC25: EB | AD25: EB | AF25: AP | AI25: EB | AN25: {=IF(LEFT(B25,1)="3","x",IFNA(LET(raw,XLOOKUP(C25,'Follow up.2'!B:B,'Follow up.2'!AF:AF),IF(OR(raw="",raw=0),"-",TEXT(MIN(--raw,DATE(2027,6,1)),"mm/yyyy"))),"-"))} -> -
B26: {=ifna(iferror(xlookup(C:C,'1000'!A:A,'1000'!D:D),iferror(xlookup(C:C,'2000'!A:A,'2000'!D:D),xlookup(C:C,'3000'!A:A,'3000'!D:D))),"-")} -> 1005 | C26: 57 | D26: Laughlin she/her | E26: Monahan | F26: Female | G26: 8 | H26: Megan Monahan | I26: (530) 263-7370 | J26: (530) 263-7370 | M26: Sibling is 1113 | N26: schedule WAVE3 v1- july date she wants | O26: 46196 | P26: DZ | Q26: DZ | R26: DZ | S26: DZ | T26: DZ | U26: DZ | V26: DZ | W26: DZ | X26: DZ | Y26: DZ | Z26: {=IFERROR(xlookup(C:C,'Follow up.1'!A:A,'Follow up.1'!AF:AF),"-")} -> 10/24 | AA26: SB | AB26: DZ | AC26: DZ | AD26: DZ | AF26: DZ | AG26: AD | AI26: DZ | AJ26: DZ | AK26: DZ | AL26: DZ | AM26: n/a | AN26: {=IF(LEFT(B26,1)="3","x",IFNA(LET(raw,XLOOKUP(C26,'Follow up.2'!B:B,'Follow up.2'!AF:AF),IF(OR(raw="",raw=0),"-",TEXT(MIN(--raw,DATE(2027,6,1)),"mm/yyyy"))),"-"))} -> 03/2026 | AO26: EB | AP26: EB | AQ26: EB
B27: {=ifna(iferror(xlookup(C:C,'1000'!A:A,'1000'!D:D),iferror(xlookup(C:C,'2000'!A:A,'2000'!D:D),xlookup(C:C,'3000'!A:A,'3000'!D:D))),"-")} -> 1130 | C27: 1927 | D27: Zarriah | E27: Williams | F27: Female (1) | G27: 11 | H27: Cherele washington | I27: (267) 628-8662 | L27: redcap - sibling in study | N27: Wave 2 initial contact | O27: 46197 | P27: MV | Q27: MV | R27: AK | S27: AK | T27: CP | U27: CP | V27: AD | W27: AK | X27: MV | Y27: CP | Z27: {=IFERROR(xlookup(C:C,'Follow up.1'!A:A,'Follow up.1'!AF:AF),"-")} -> 07/26 | AN27: {=IF(LEFT(B27,1)="3","x",IFNA(LET(raw,XLOOKUP(C27,'Follow up.2'!B:B,'Follow up.2'!AF:AF),IF(OR(raw="",raw=0),"-",TEXT(MIN(--raw,DATE(2027,6,1)),"mm/yyyy"))),"-"))} -> -
B28: {=ifna(iferror(xlookup(C:C,'1000'!A:A,'1000'!D:D),iferror(xlookup(C:C,'2000'!A:A,'2000'!D:D),xlookup(C:C,'3000'!A:A,'3000'!D:D))),"-")} -> 1002 | C28: 47 | D28: Vihaan | E28: Kaushik | G28: 10 | I28: (919) 428-0818 | J28: (919) 428-0818 | N28: Wave 3 schedule screener (travelling til end of july) | O28: 46202 | P28: AM | Q28: AM | R28: AM | S28: AM | T28: AM | U28: AM | V28: DZ | W28: BS | X28: BS | Y28: MV | Z28: {=IFERROR(xlookup(C:C,'Follow up.1'!A:A,'Follow up.1'!AF:AF),"-")} -> 10/24 | AA28: MV | AB28: MV | AC28: BS | AD28: BS | AF28: TP | AG28: MV | AI28: TP | AJ28: MV | AK28: Mv | AL28: MV | AM28: n/a | AN28: {=IF(LEFT(B28,1)="3","x",IFNA(LET(raw,XLOOKUP(C28,'Follow up.2'!B:B,'Follow up.2'!AF:AF),IF(OR(raw="",raw=0),"-",TEXT(MIN(--raw,DATE(2027,6,1)),"mm/yyyy"))),"-"))} -> 05/2026
B29: {=ifna(iferror(xlookup(C:C,'1000'!A:A,'1000'!D:D),iferror(xlookup(C:C,'2000'!A:A,'2000'!D:D),xlookup(C:C,'3000'!A:A,'3000'!D:D))),"-")} -> 2006 | C29: 48 | D29: Vrishab | E29: Kaushik | G29: 13 | H29: Dhivya Kaushik | I29: dhivyac@gmail.com | J29: (919) 428-0818 | N29: Wave 3 schedule screener (travelling til end of july) | O29: 46202 | P29: DZ | Q29: DZ | R29: DZ | S29: DZ | T29: DZ | U29: DZ | V29: DZ | W29: DZ | X29: DZ | Y29: DZ | Z29: {=IFERROR(xlookup(C:C,'Follow up.1'!A:A,'Follow up.1'!AF:AF),"-")} -> 10/24 | AA29: MV | AB29: MV | AC29: BS | AD29: BS | AF29: KL | AG29: MV | AI29: TP | AJ29: MV | AK29: MV | AL29: MV | AM29: n/a | AN29: {=IF(LEFT(B29,1)="3","x",IFNA(LET(raw,XLOOKUP(C29,'Follow up.2'!B:B,'Follow up.2'!AF:AF),IF(OR(raw="",raw=0),"-",TEXT(MIN(--raw,DATE(2027,6,1)),"mm/yyyy"))),"-"))} -> 04/2026 | AO29: CP
B30: {=ifna(iferror(xlookup(C:C,'1000'!A:A,'1000'!D:D),iferror(xlookup(C:C,'2000'!A:A,'2000'!D:D),xlookup(C:C,'3000'!A:A,'3000'!D:D))),"-")} -> 2111 | C30: 1765 | D30: Emani | E30: wooden | F30: Female (1) | G30: 15 | I30: (267) 699-1405 | J30: (267) 560-6952 | L30: CLINICONTACT | N30: schedule screener - called mom but she couldn't hear- ghosting? | O30: 46202 | P30: KL | Q30: MV | R30: MV | S30: MV | T30: MV | U30: MV | V30: MV | W30: AK | X30: AK | Y30: MV | Z30: {=IFERROR(xlookup(C:C,'Follow up.1'!A:A,'Follow up.1'!AF:AF),"-")} -> 04/26 | AA30: BH | AN30: {=IF(LEFT(B30,1)="3","x",IFNA(LET(raw,XLOOKUP(C30,'Follow up.2'!B:B,'Follow up.2'!AF:AF),IF(OR(raw="",raw=0),"-",TEXT(MIN(--raw,DATE(2027,6,1)),"mm/yyyy"))),"-"))} -> -
B31: {=ifna(iferror(xlookup(C:C,'1000'!A:A,'1000'!D:D),iferror(xlookup(C:C,'2000'!A:A,'2000'!D:D),xlookup(C:C,'3000'!A:A,'3000'!D:D))),"-")} -> 1129 | C31: 1781 | D31: Za'Haad | E31: Covington-Walley | F31: Male (2) | G31: 10 | H31: Erica Covington | I31: (215) 397-7672 | J31: (215) 397-7672 | L31: CLINICONTACT | N31: Wave 2 intial content (if no scan no w3) | O31: 46204 | P31: KL | Q31: MV | R31: KL | S31: KL | T31: MV | U31: MV | V31: KL | W31: KL | X31: IA | Y31: AMo | Z31: {=IFERROR(xlookup(C:C,'Follow up.1'!A:A,'Follow up.1'!AF:AF),"-")} -> 07/26 | AN31: {=IF(LEFT(B31,1)="3","x",IFNA(LET(raw,XLOOKUP(C31,'Follow up.2'!B:B,'Follow up.2'!AF:AF),IF(OR(raw="",raw=0),"-",TEXT(MIN(--raw,DATE(2027,6,1)),"mm/yyyy"))),"-"))} -> -
B32: {=ifna(iferror(xlookup(C:C,'1000'!A:A,'1000'!D:D),iferror(xlookup(C:C,'2000'!A:A,'2000'!D:D),xlookup(C:C,'3000'!A:A,'3000'!D:D))),"-")} -> 1011 | C32: 76 | D32: Caleb | E32: Davis | F32: M | G32: 12 | H32: Rebecca davis | I32: (215) 498-6017 | N32: Wave 3 intial contact (not on a team list but good contact and age?) | O32: 46204 | P32: DZ | Q32: BS | R32: BS | S32: BS | T32: BS | U32: BS | V32: MV | W32: DZ | X32: DZ | Y32: DZ | Z32: {=IFERROR(xlookup(C:C,'Follow up.1'!A:A,'Follow up.1'!AF:AF),"-")} -> 10/24 | AA32: TP | AB32: CP | AC32: DZ | AD32: DZ | AF32: KL | AG32: TP | AI32: CP | AJ32: TP | AK32: KL | AL32: CP | AM32: n/a | AN32: {=IF(LEFT(B32,1)="3","x",IFNA(LET(raw,XLOOKUP(C32,'Follow up.2'!B:B,'Follow up.2'!AF:AF),IF(OR(raw="",raw=0),"-",TEXT(MIN(--raw,DATE(2027,6,1)),"mm/yyyy"))),"-"))} -> 07/2026 | AO32: 46204
B33: {=ifna(iferror(xlookup(C:C,'1000'!A:A,'1000'!D:D),iferror(xlookup(C:C,'2000'!A:A,'2000'!D:D),xlookup(C:C,'3000'!A:A,'3000'!D:D))),"-")} -> 2126 | C33: 1883 | D33: Makynzi | E33: jones | F33: Female (1) | G33: 13 | H33: Brittani Jones | I33: 2154105186 | J33: 2677098301 | L33: CLINICONTACT | N33: Wave 2 Initial Contact- if issues with scanner no w3 | O33: 46204 | P33: MV | Q33: MV | R33: DZ | S33: CP | T33: CP | U33: MV | V33: CP | W33: CP | X33: IA | Y33: CP | Z33: {=IFERROR(xlookup(C:C,'Follow up.1'!A:A,'Follow up.1'!AF:AF),"-")} -> 07/26 | AN33: {=IF(LEFT(B33,1)="3","x",IFNA(LET(raw,XLOOKUP(C33,'Follow up.2'!B:B,'Follow up.2'!AF:AF),IF(OR(raw="",raw=0),"-",TEXT(MIN(--raw,DATE(2027,6,1)),"mm/yyyy"))),"-"))} -> -
B34: {=ifna(iferror(xlookup(C:C,'1000'!A:A,'1000'!D:D),iferror(xlookup(C:C,'2000'!A:A,'2000'!D:D),xlookup(C:C,'3000'!A:A,'3000'!D:D))),"-")} -> 2127 | C34: 1862 | D34: Isaiah | E34: Scott | F34: Male (2) | G34: 14 | H34: Felicia Wrice-Scott | I34: (267) 738-1138 | J34: (267) 586-7726 | K34: fwrice76@gmail.com | L34: CLINICONTACT | N34: Wave 2 Initial Contact | O34: 46204 | P34: CP | Q34: MV | R34: DZ | S34: MV | T34: AM | U34: MV | V34: CP | W34: IA | X34: MV | Y34: IA | Z34: {=IFERROR(xlookup(C:C,'Follow up.1'!A:A,'Follow up.1'!AF:AF),"-")} -> 07/26 | AN34: {=IF(LEFT(B34,1)="3","x",IFNA(LET(raw,XLOOKUP(C34,'Follow up.2'!B:B,'Follow up.2'!AF:AF),IF(OR(raw="",raw=0),"-",TEXT(MIN(--raw,DATE(2027,6,1)),"mm/yyyy"))),"-"))} -> -
B35: {=ifna(iferror(xlookup(C:C,'1000'!A:A,'1000'!D:D),iferror(xlookup(C:C,'2000'!A:A,'2000'!D:D),xlookup(C:C,'3000'!A:A,'3000'!D:D))),"-")} -> 2119 | C35: 1867 | D35: Maia | E35: LaMonte | F35: Female (1) | G35: 15 | H35: April LaMonte | I35: (484) 888-6718 | J35: (484) 888-6718 | K35: thelamontefamily@gmail.com | L35: CLINICONTACT | N35: Wave 2 Initial contact | O35: 46204 | P35: CP | Q35: MS | R35: AD | S35: AD | T35: Kl | U35: KL | V35: AM | W35: CP | X35: IA | Y35: MV | Z35: {=IFERROR(xlookup(C:C,'Follow up.1'!A:A,'Follow up.1'!AF:AF),"-")} -> 07/26 | AN35: {=IF(LEFT(B35,1)="3","x",IFNA(LET(raw,XLOOKUP(C35,'Follow up.2'!B:B,'Follow up.2'!AF:AF),IF(OR(raw="",raw=0),"-",TEXT(MIN(--raw,DATE(2027,6,1)),"mm/yyyy"))),"-"))} -> -
B36: {=ifna(iferror(xlookup(C:C,'1000'!A:A,'1000'!D:D),iferror(xlookup(C:C,'2000'!A:A,'2000'!D:D),xlookup(C:C,'3000'!A:A,'3000'!D:D))),"-")} -> 2125 | C36: 1884 | D36: Kyrah | E36: Ferguson | F36: Female (1) | G36: 15 | H36: Safiyyah Carter Pack | I36: (267) 648-6297 | J36: 2159173433 | L36: CLINICONTACT | N36: Wave 2 intial contact | O36: 46204 | P36: IA | Q36: MV | R36: IA | S36: IA | T36: CP | U36: MV | V36: MV | W36: MV | X36: KL | Y36: MV | Z36: {=IFERROR(xlookup(C:C,'Follow up.1'!A:A,'Follow up.1'!AF:AF),"-")} -> 07/26 | AN36: {=IF(LEFT(B36,1)="3","x",IFNA(LET(raw,XLOOKUP(C36,'Follow up.2'!B:B,'Follow up.2'!AF:AF),IF(OR(raw="",raw=0),"-",TEXT(MIN(--raw,DATE(2027,6,1)),"mm/yyyy"))),"-"))} -> -
B37: {=ifna(iferror(xlookup(C:C,'1000'!A:A,'1000'!D:D),iferror(xlookup(C:C,'2000'!A:A,'2000'!D:D),xlookup(C:C,'3000'!A:A,'3000'!D:D))),"-")} -> 2117 | C37: 1855 | D37: Beniris | E37: Cumbe-Gonzalez | F37: Female (1) | G37: 16 | H37: Beniris C-G | I37: 787-549-0402 | J37: (215) 209-9982 | K37: beniriscristal@gmail.com | L37: CLINICONTACT | N37: dont contact until avi clears - w2 initial | O37: 46204 | P37: MV | Q37: MV | R37: MV | S37: MV | T37: CP | U37: KL | V37: MV | W37: CP | X37: KL | Y37: MV | Z37: {=IFERROR(xlookup(C:C,'Follow up.1'!A:A,'Follow up.1'!AF:AF),"-")} -> 07/26 | AN37: {=IF(LEFT(B37,1)="3","x",IFNA(LET(raw,XLOOKUP(C37,'Follow up.2'!B:B,'Follow up.2'!AF:AF),IF(OR(raw="",raw=0),"-",TEXT(MIN(--raw,DATE(2027,6,1)),"mm/yyyy"))),"-"))} -> -
B38: {=ifna(iferror(xlookup(C:C,'1000'!A:A,'1000'!D:D),iferror(xlookup(C:C,'2000'!A:A,'2000'!D:D),xlookup(C:C,'3000'!A:A,'3000'!D:D))),"-")} -> 2130 | C38: 1835 | D38: Zariyah | E38: Covington | F38: Female (1) | G38: 16 | H38: Erica Covington | I38: (215) 397-7672 | L38: Sibling is 1781 | N38: Wave 2 inital contact | O38: 46204 | P38: KL | Q38: KL | R38: KL | S38: AK | T38: KL | U38: AD | V38: KL | W38: KL | X38: IA | Y38: MV | Z38: {=IFERROR(xlookup(C:C,'Follow up.1'!A:A,'Follow up.1'!AF:AF),"-")} -> 07/26 | AN38: {=IF(LEFT(B38,1)="3","x",IFNA(LET(raw,XLOOKUP(C38,'Follow up.2'!B:B,'Follow up.2'!AF:AF),IF(OR(raw="",raw=0),"-",TEXT(MIN(--raw,DATE(2027,6,1)),"mm/yyyy"))),"-"))} -> -
B39: {=ifna(iferror(xlookup(C:C,'1000'!A:A,'1000'!D:D),iferror(xlookup(C:C,'2000'!A:A,'2000'!D:D),xlookup(C:C,'3000'!A:A,'3000'!D:D))),"-")} -> 1012 | C39: 169 | D39: Magnolia (Maggie) | E39: Becker | F39: F | H39: Justin Becker (dad) Sarah becker (mom) | N39: Wave 3 initial contact | O39: 46204 | P39: MV | Q39: MV | R39: MV | S39: MV | T39: MV | U39: MV | V39: MV | W39: MV | X39: MV | Y39: MV | Z39: {=IFERROR(xlookup(C:C,'Follow up.1'!A:A,'Follow up.1'!AF:AF),"-")} -> 10/24 | AA39: AM | AB39: AM | AC39: AM | AD39: AM | AF39: KL | AG39: CP | AI39: KL | AJ39: CP | AK39: CP | AL39: KL | AM39: n/a | AN39: {=IF(LEFT(B39,1)="3","x",IFNA(LET(raw,XLOOKUP(C39,'Follow up.2'!B:B,'Follow up.2'!AF:AF),IF(OR(raw="",raw=0),"-",TEXT(MIN(--raw,DATE(2027,6,1)),"mm/yyyy"))),"-"))} -> 06/2026 | AO39: 46204
B40: {=ifna(iferror(xlookup(C:C,'1000'!A:A,'1000'!D:D),iferror(xlookup(C:C,'2000'!A:A,'2000'!D:D),xlookup(C:C,'3000'!A:A,'3000'!D:D))),"-")} -> 1017 | C40: 115 | D40: Iyannah | E40: Marshall* | I40: (609) 929-2222 | J40: (609) 929-2222 | N40: Wave 3 Initial Contact | O40: 46204 | P40: DZ | Q40: BS | R40: BS | S40: BS | T40: BS | U40: BS | V40: MV | W40: MV | X40: MV | Y40: MV | Z40: {=IFERROR(xlookup(C:C,'Follow up.1'!A:A,'Follow up.1'!AF:AF),"-")} -> 2/25 | AA40: MV | AB40: MV | AC40: MV | AD40: MV | AF40: CP | AG40: KL | AI40: DZ | AJ40: DZ | AK40: DZ | AL40: DZ | AM40: n/a | AN40: {=IF(LEFT(B40,1)="3","x",IFNA(LET(raw,XLOOKUP(C40,'Follow up.2'!B:B,'Follow up.2'!AF:AF),IF(OR(raw="",raw=0),"-",TEXT(MIN(--raw,DATE(2027,6,1)),"mm/yyyy"))),"-"))} -> 07/2026 | AO40: 46204
...

Sheet Scheduling Eligibility
C1: When editing this sheet DO NOT use copy/paste
I2: Scan | K2: Scan shadow MUST BE ACCOMPANIED BY L3 and L2 | M2: V1 | P2: Signups - do not count for marks
B3: Initials | C3: Researchers | D3: Visit Tally since 1/1/2025 | I3: L3 | J3: L2 | K3: L3 | L3: L2 | M3: V1 | N3: V1 Shadow (must be with someone who can do V1) | P3: Screeners | V3: 3/20/2025 to 5/31/2025 Scanning Tally | X3: 6/1/2025 to 1/19/2026 Scanning Tally | AI3: 2
B4: AP | C4: Anushka | D4: 15 | I4: =if('Scheduling Code'!N3="x","",'Scheduling Code'!N3) -> Shenghan | J4: =if('Scheduling Code'!O3="x","",'Scheduling Code'!O3) -> Isabel | K4: =if('Scheduling Code'!P3="x","",'Scheduling Code'!P3) -> Camilla | L4: =if('Scheduling Code'!Q3="x","",'Scheduling Code'!Q3) -> Aashna | M4: =if('Scheduling Code'!R3="x","",'Scheduling Code'!R3) -> Aashna | N4: =if('Scheduling Code'!S3="x","",'Scheduling Code'!S3) -> Kiara | P4: Megan | V4: Avi | W4: 30 | X4: Avi Dachs | Y4: 42 | AI4: 1
B5: AD | C5: Avi | D5: 20 | I5: =if('Scheduling Code'!N4="x","",'Scheduling Code'!N4) -> Danny | J5: =if('Scheduling Code'!O4="x","",'Scheduling Code'!O4) -> Maia | K5: =if('Scheduling Code'!P4="x","",'Scheduling Code'!P4) -> Sophie | L5: =if('Scheduling Code'!Q4="x","",'Scheduling Code'!Q4) -> Shenghan | M5: =if('Scheduling Code'!R4="x","",'Scheduling Code'!R4) -> Alicia | N5: =if('Scheduling Code'!S4="x","",'Scheduling Code'!S4) | P5: Emily | V5: Danny | W5: 29 | X5: Megan Vince | Y5: 36 | AI5: 35
B6: MV | C6: Megan | D6: 17 | I6: =if('Scheduling Code'!N5="x","",'Scheduling Code'!N5) -> Lina | J6: =if('Scheduling Code'!O5="x","",'Scheduling Code'!O5) -> Camilla | K6: =if('Scheduling Code'!P5="x","",'Scheduling Code'!P5) -> Anushka | L6: =if('Scheduling Code'!Q5="x","",'Scheduling Code'!Q5) -> Alicia | M6: =if('Scheduling Code'!R5="x","",'Scheduling Code'!R5) -> Emily | N6: =if('Scheduling Code'!S5="x","",'Scheduling Code'!S5) | P6: Avi | V6: Megan | W6: 28 | X6: Abby Kennedy | Y6: 4 | AI6: 11
B7: AK | C7: Abby | D7: 8 | I7: =if('Scheduling Code'!N6="x","",'Scheduling Code'!N6) -> Isabel | J7: =if('Scheduling Code'!O6="x","",'Scheduling Code'!O6) -> Abby | K7: =if('Scheduling Code'!P6="x","",'Scheduling Code'!P6) | L7: =if('Scheduling Code'!Q6="x","",'Scheduling Code'!Q6) -> Emily | M7: =if('Scheduling Code'!R6="x","",'Scheduling Code'!R6) -> Sophie | N7: =if('Scheduling Code'!S6="x","",'Scheduling Code'!S6) | P7: Abby | V7: Maia | W7: 8 | X7: Andrew Cardona | Y7: 16 | AI7: 347
B8: AC | C8: Andrew | D8: 17 | I8: =if('Scheduling Code'!N7="x","",'Scheduling Code'!N7) -> Andrew | J8: =if('Scheduling Code'!O7="x","",'Scheduling Code'!O7) -> Anushka | K8: =if('Scheduling Code'!P7="x","",'Scheduling Code'!P7) | L8: =if('Scheduling Code'!Q7="x","",'Scheduling Code'!Q7) -> Kiara | M8: =if('Scheduling Code'!R7="x","",'Scheduling Code'!R7) -> Rae | N8: =if('Scheduling Code'!S7="x","",'Scheduling Code'!S7) | P8: Andrew | V8: Isabel | W8: 7 | X8: Kirsten | Y8: 33 | AI8: 388
B9: KD | C9: Kiara | D9: 4 | I9: =if('Scheduling Code'!N8="x","",'Scheduling Code'!N8) -> Megan | J9: =if('Scheduling Code'!O8="x","",'Scheduling Code'!O8) -> Andrew | L9: =if('Scheduling Code'!Q8="x","",'Scheduling Code'!Q8) -> Sophie | M9: =if('Scheduling Code'!R8="x","",'Scheduling Code'!R8) -> Maia | N9: =if('Scheduling Code'!S8="x","",'Scheduling Code'!S8) | P9: Rae - training | V9: Kirsten | W9: 6 | X9: Binh | Y9: 25 | AI9: 1220
B10: DZ | C10: Danny | D10: 8 | I10: =if('Scheduling Code'!N9="x","",'Scheduling Code'!N9) -> Avi | J10: =if('Scheduling Code'!O9="x","",'Scheduling Code'!O9) -> Megan | K10: =if('Scheduling Code'!P9="x","",'Scheduling Code'!P9) | L10: =if('Scheduling Code'!Q9="x","",'Scheduling Code'!Q9) -> Rae | M10: =if('Scheduling Code'!R9="x","",'Scheduling Code'!R9) -> Camilla | N10: =if('Scheduling Code'!S9="x","",'Scheduling Code'!S9) | P10: Maia | V10: Binh | W10: 5 | X10: Ife | Y10: 5 | AI10: 2483
B11: AH | C11: Alicia | D11: 3 | I11: =if('Scheduling Code'!N10="x","",'Scheduling Code'!N10) | J11: =if('Scheduling Code'!O10="x","",'Scheduling Code'!O10) -> Avi | K11: =if('Scheduling Code'!P10="x","",'Scheduling Code'!P10) | L11: =if('Scheduling Code'!Q10="x","",'Scheduling Code'!Q10) | M11: =if('Scheduling Code'!R10="x","",'Scheduling Code'!R10) -> Abby | N11: =if('Scheduling Code'!S10="x","",'Scheduling Code'!S10) | P11: Binh | V11: Aashna | W11: 5 | X11: Camilla | Y11: 5 | AI11: 0
B12: CP | C12: Camilla | D12: 7 | I12: =if('Scheduling Code'!N11="x","",'Scheduling Code'!N11) | J12: =if('Scheduling Code'!O11="x","",'Scheduling Code'!O11) | K12: =if('Scheduling Code'!P11="x","",'Scheduling Code'!P11) | L12: =if('Scheduling Code'!Q11="x","",'Scheduling Code'!Q11) | M12: =if('Scheduling Code'!R11="x","",'Scheduling Code'!R11) -> Anushka | N12: =if('Scheduling Code'!S11="x","",'Scheduling Code'!S11) | P12: Sophie | V12: Sophie | W12: 4 | X12: Maia | Y12: 4 | AI12: 62
B13: MS | C13: Maia | D13: 7 | I13: =if('Scheduling Code'!N12="x","",'Scheduling Code'!N12) | J13: =if('Scheduling Code'!O12="x","",'Scheduling Code'!O12) | K13: =if('Scheduling Code'!P12="x","",'Scheduling Code'!P12) | M13: =if('Scheduling Code'!R12="x","",'Scheduling Code'!R12) -> Andrew | N13: =if('Scheduling Code'!S12="x","",'Scheduling Code'!S12) | P13: Camilla | V13: Harry | W13: 4 | X13: Aashna | Y13: 3 | AI13: 572
B14: AM | C14: Aashna | D14: 2 | I14: =if('Scheduling Code'!N13="x","",'Scheduling Code'!N13) | J14: =if('Scheduling Code'!O13="x","",'Scheduling Code'!O13) | K14: =if('Scheduling Code'!P13="x","",'Scheduling Code'!P13) | L14: =if('Scheduling Code'!Q13="x","",'Scheduling Code'!Q13) | M14: =if('Scheduling Code'!R13="x","",'Scheduling Code'!R13) -> Megan | N14: =if('Scheduling Code'!S13="x","",'Scheduling Code'!S13) | V14: Brooke | W14: 4 | X14: Isabel | Y14: 8 | AI14: 22
B15: IL | C15: Isabel | D15: 6 | I15: =if('Scheduling Code'!N14="x","",'Scheduling Code'!N14) | J15: =if('Scheduling Code'!O14="x","",'Scheduling Code'!O14) | K15: =if('Scheduling Code'!P14="x","",'Scheduling Code'!P14) | L15: =if('Scheduling Code'!Q14="x","",'Scheduling Code'!Q14) | M15: =if('Scheduling Code'!R14="x","",'Scheduling Code'!R14) -> Avi | N15: =if('Scheduling Code'!S14="x","",'Scheduling Code'!S14) | V15: Ife | W15: 3 | X15: Lina | Y15: 2 | AI15: 149
B16: LH | C16: Lina | D16: 4 | I16: =if('Scheduling Code'!N15="x","",'Scheduling Code'!N15) | J16: =if('Scheduling Code'!O15="x","",'Scheduling Code'!O15) | K16: =if('Scheduling Code'!P15="x","",'Scheduling Code'!P15) | L16: =if('Scheduling Code'!Q15="x","",'Scheduling Code'!Q15) | M16: =if('Scheduling Code'!R15="x","",'Scheduling Code'!R15) | N16: =if('Scheduling Code'!S15="x","",'Scheduling Code'!S15) | V16: Rae | W16: 2 | X16: Shenghan | Y16: 4 | AI16: 109
B17: SW | C17: Shenghan | D17: 3 | I17: =if('Scheduling Code'!N16="x","",'Scheduling Code'!N16) | J17: =if('Scheduling Code'!O16="x","",'Scheduling Code'!O16) | K17: =if('Scheduling Code'!P16="x","",'Scheduling Code'!P16) | L17: =if('Scheduling Code'!Q16="x","",'Scheduling Code'!Q16) | M17: =if('Scheduling Code'!R16="x","",'Scheduling Code'!R16) | N17: =if('Scheduling Code'!S16="x","",'Scheduling Code'!S16) | V17: Titiksha | W17: 1 | X17: Rae | Y17: 4 | AI17: 405
B18: RY | C18: Rae | D18: 7 | I18: =if('Scheduling Code'!N17="x","",'Scheduling Code'!N17) | J18: =if('Scheduling Code'!O17="x","",'Scheduling Code'!O17) | K18: =if('Scheduling Code'!P17="x","",'Scheduling Code'!P17) | L18: =if('Scheduling Code'!Q17="x","",'Scheduling Code'!Q17) | M18: =if('Scheduling Code'!R17="x","",'Scheduling Code'!R17) | N18: =if('Scheduling Code'!S17="x","",'Scheduling Code'!S17) | V18: Shenghan | W18: 1 | X18: Sophie | Y18: 4 | AI18: 34
B19: SM | C19: Sophie | D19: 5 | I19: =if('Scheduling Code'!N18="x","",'Scheduling Code'!N18) | J19: =if('Scheduling Code'!O18="x","",'Scheduling Code'!O18) | K19: =if('Scheduling Code'!P18="x","",'Scheduling Code'!P18) | L19: =if('Scheduling Code'!Q18="x","",'Scheduling Code'!Q18) | M19: =if('Scheduling Code'!R18="x","",'Scheduling Code'!R18) | N19: =if('Scheduling Code'!S18="x","",'Scheduling Code'!S18) | V19: Samra | W19: 1 | X19: Emily | Y19: 2 | AI19: 1
B20: EB | C20: Emily | D20: 4 | I20: =if('Scheduling Code'!N19="x","",'Scheduling Code'!N19) | J20: =if('Scheduling Code'!O19="x","",'Scheduling Code'!O19) | K20: =if('Scheduling Code'!P19="x","",'Scheduling Code'!P19) | L20: =if('Scheduling Code'!Q19="x","",'Scheduling Code'!Q19) | M20: =if('Scheduling Code'!R19="x","",'Scheduling Code'!R19) | N20: =if('Scheduling Code'!S19="x","",'Scheduling Code'!S19) | V20: Jay | W20: 1 | AI20: 35
B21: SB | C21: Samra | D21: 3 | I21: =if('Scheduling Code'!N20="x","",'Scheduling Code'!N20) | J21: =if('Scheduling Code'!O20="x","",'Scheduling Code'!O20) | K21: =if('Scheduling Code'!P20="x","",'Scheduling Code'!P20) | L21: =if('Scheduling Code'!Q20="x","",'Scheduling Code'!Q20) | M21: =if('Scheduling Code'!R20="x","",'Scheduling Code'!R20) | N21: =if('Scheduling Code'!S20="x","",'Scheduling Code'!S20) | V21: Cooper (???) | W21: 1 | AI21: 83
B22: NM | C22: Natalie | I22: =if('Scheduling Code'!N21="x","",'Scheduling Code'!N21) | V22: Lina | W22: 0 | AI22: 3
V23: Camilla | W23: 0
V24: Abby | W24: 0

Sheet 1000
B2: participant dropped out of the study or stopped responding
B3: unsusable data
B4: Excused no-show/partial visit | G4: VISIT 1 | M4: VISIT 2 | U4: Wave 2 Visit 1 | AC4: Wave 2 Visit 2 | AN4: Wave 3 Visit 1 | AV4: Wave 3 Visit 2
B5: Completed visit
B6: No Mri Moving Forward
A7: Record ID | B7: First name | C7: Last name | D7: PID | G7: Date | H7: RAs | I7: Notes | J7: Data transferred? | M7: Date | N7: RAs | O7: Notes | P7: X-NAT data | Q7: Behavioral data | R7: Compensation? | U7: Date | V7: RA | W7: Shadow RA | X7: Notes | Y7: Behavioral data | Z7: Compensation? | AC7: Date | AD7: L3 RA | AE7: L2 RA | AF7: Shadow 1 | AG7: Shadow 2 | AH7: Notes | AI7: X-NAT data | AJ7: Behavioral data | AK7: Compensation? | AN7: Date | AO7: RA | AP7: Shadow RA | AQ7: Notes | AR7: Behavioral data | AS7: Compensation? | AV7: Date | AW7: L3 | AX7: L2 | AY7: Shadow 1 | AZ7: Shadow 2 | BA7: Notes | BB7: X-NAT data | BC7: Behavioral data | BD7: Compensation?
A8: 46 | B8: {=IFNA(XLOOKUP(A8,'New Signups'!C:C,'New Signups'!D:D),"-")} -> Naylah | C8: {=IFNA(XLOOKUP(A8,'New Signups'!C:C,'New Signups'!E:E),"-")} -> Hopkins | D8: 1001 | G8: 45029 | H8: King | I8: Long session, ran half hour over; good participant | J8: Y | M8: 45019 | N8: Skalaban/Murray/King | O8: Visit ran long; participant didn't understand Chatroom very well. Kept falling asleep but tried her best. | P8: Y | Q8: Y | R8: Y
A9: 47 | B9: {=IFNA(XLOOKUP(A9,'New Signups'!C:C,'New Signups'!D:D),"-")} -> Vihaan | C9: {=IFNA(XLOOKUP(A9,'New Signups'!C:C,'New Signups'!E:E),"-")} -> Kaushik | D9: 1002 | E9: 1 | F9: 1 | G9: 45037 | H9: Murray | I9: No notes; good session | J9: Y | M9: 45065 | N9: Skalaban/King | O9: Did very well, got a little frustrated during GNG (button presses). | P9: Y | Q9: Y | R9: Y | U9: 45675 | V9: Megan | X9: for pat icons put 1002.2 not 10022 but not for peers. Also, he was like spamming keys for shortant | Y9: y | Z9: y | AC9: 45701 | AD9: Danny | AE9: Megan | AH9: good session - localizer and fieldmaps again after 2nd round of gng | AI9: Y | AJ9: Y | AK9: Y
A10: 57 | B10: {=IFNA(XLOOKUP(A10,'New Signups'!C:C,'New Signups'!D:D),"-")} -> Laughlin she/her | C10: {=IFNA(XLOOKUP(A10,'New Signups'!C:C,'New Signups'!E:E),"-")} -> Monahan | D10: 1005 | E10: 1 | F10: 1 | G10: 45118 | H10: Murray/Shulski | I10: great session; would like to see an image of her brain | J10: Y | M10: 45126 | N10: Murray/King | O10: did not get to DTI | P10: Y | Q10: Y | R10: Y | U10: 45657 | V10: Danny | X10: answered MTES questions regaruding IPAD | Y10: Y | Z10: Y | AC10: 45634 | AD10: Danny | AE10: Megan | AH10: good session no notes | AI10: Y | AJ10: Y | AK10: Y
A11: 63 | B11: {=IFNA(XLOOKUP(A11,'New Signups'!C:C,'New Signups'!D:D),"-")} -> Elizabeth | C11: {=IFNA(XLOOKUP(A11,'New Signups'!C:C,'New Signups'!E:E),"-")} -> Lem | D11: 1006 | E11: 1 | F11: 1 | G11: 45118 | H11: Wyatt | I11: Great session and participant! Session ran about a half an hour over time, but completed everything after moving to 841. Data for gameofdice and stoplight was not transferred (done in 844 and room was occupied). Would like to see an image of her brain | J11: Y | M11: 45126 | N11: Murray/King | O11: did not get to DTI | P11: Y | Q11: Y | R11: Y | U11: 45761 | V11: Sophie | X11: good session, no notes | Y11: Y | Z11: Y | AC11: 45817 | AD11: Megan | AE11: Binh | AH11: didn't run dd social, participant had braces | AI11: Y | AJ11: Y
A12: 75 | B12: {=IFNA(XLOOKUP(A12,'New Signups'!C:C,'New Signups'!D:D),"-")} -> Sadie | C12: {=IFNA(XLOOKUP(A12,'New Signups'!C:C,'New Signups'!E:E),"-")} -> Davis | D12: 1018 | E12: 1 | F12: 1 | G12: 45216 | H12: Zweben/Neil | I12: good session | J12: Y | M12: 45233 | N12: Murray/King/Zweben | O12: She did awesome, struggled a bit eith PAT at first but got it, had a hard time with planet gonogo but did her best - she is very young | P12: Y | Q12: Y | R12: Y | U12: 45744 | V12: Rae | W12: Megan | X12: No notes, good session | Y12: y | Z12: y | AC12: 45778 | AD12: Danny | AE12: Avi | AH12: No notes good session | AI12: y | AJ12: y | AK12: y
A13: 76 | B13: {=IFNA(XLOOKUP(A13,'New Signups'!C:C,'New Signups'!D:D),"-")} -> Caleb | C13: {=IFNA(XLOOKUP(A13,'New Signups'!C:C,'New Signups'!E:E),"-")} -> Davis | D13: 1011 | E13: 1 | F13: 1 | G13: 45105 | H13: King | I13: Great session; finished in an hour. Seemed attentive | J13: Y | M13: 45118 | N13: King | O13: good session went well | P13: Y | Q13: Y | R13: Y | U13: 45744 | V13: Sophie | X13: put 2 instead of 1 for group number | Y13: Y | Z13: Y | AC13: 45769 | AD13: Isabel | AE13: Samra | AF13: Danny | AH13: No 2nd round of PAT - had to skip | AI13: Y | AJ13: Y | AK13: Y
A14: 96 | B14: {=IFNA(XLOOKUP(A14,'New Signups'!C:C,'New Signups'!D:D),"-")} -> Ari | C14: {=IFNA(XLOOKUP(A14,'New Signups'!C:C,'New Signups'!E:E),"-")} -> Woodward | D14: 1009 | E14: 1 | F14: 1 | G14: 45097 | H14: Wyatt | I14: Bored often, coversational, couldn't complete short ant or uberball due to time - ANSWERED MTES/SAS/OBJ about IPAD | J14: Y | M14: 45127 | N14: King/Murray | O14: After the scan was tired and didn't want to be here anymore. Had to take him upstairs for uberball and short ANT that was not completed in his v1, but our inquisit license expired so I could not run either of the two tasks. For foraging task - lost him in this game- was very uninterested. Was tired from the scan. | P14: Y | Q14: Y | R14: Y
A15: 115 | B15: {=IFNA(XLOOKUP(A15,'New Signups'!C:C,'New Signups'!D:D),"-")} -> Iyannah | C15: {=IFNA(XLOOKUP(A15,'New Signups'!C:C,'New Signups'!E:E),"-")} -> Marshall* | D15: 1017 | E15: 1 | F15: 1 | G15: 45209 | H15: Zweben/King | I15: UberBall and Short Ans. not complete | J15: Y | M15: 45236 | N15: King/Murray/Shulski | O15: Forgot to run her through ANT and Uberball that was missed in visit one. Moved a lot, and got extremely tired by the 3rd round of go no go. See visit two time stamps for more specific information. | P15: Y | Q15: Y | R15: Y | U15: 45737 | V15: Maia | W15: Megan | X15: Could not sit still started to get really bored started distracting her brother didnt want to continue so skipped last survey and short ant and uberball and just did PAT but said yes to being friends with everyone | Y15: y | Z15: y | AC15: 45748 | AD15: Danny | AE15: Avi | AH15: Skipped GNG she was exhausted, fell asleep/wasn't paying attention during 2nd round of PAT. DTI sequence broken - DONT use dti data (Only 1st round PAT and T1 Usable) | AI15: Y | AJ15: Y | AK15: Y
A16: 116 | B16: {=IFNA(XLOOKUP(A16,'New Signups'!C:C,'New Signups'!D:D),"-")} -> Idris | C16: {=IFNA(XLOOKUP(A16,'New Signups'!C:C,'New Signups'!E:E),"-")} -> Marshall* | D16: 1003 | E16: 1 | F16: 1 | G16: 45084 | H16: Wyatt | I16: No notes; good session | J16: Y | M16: 45090 | N16: Skalaban/King | O16: good session went well | P16: Y | Q16: Y | R16: Y | U16: 45737 | V16: Aashna | X16: good session - hard to pay attention on flanker and uberball (little sister distracted him) | Y16: y | Z16: y | AC16: 45847 | AD16: Avi | AE16: Binh | AF16: Ife | AH16: Everything's unusable but DTI. PAT task wasn't working. He fell asleep during GnG | AI16: Y | AJ16: Y | AK16: Y
A17: 127 | B17: {=IFNA(XLOOKUP(A17,'New Signups'!C:C,'New Signups'!D:D),"-")} -> Morgan | C17: {=IFNA(XLOOKUP(A17,'New Signups'!C:C,'New Signups'!E:E),"-")} -> Weaver | D17: 1007 | E17: 1 | F17: 1 | G17: 45091 | H17: Murray | I17: Browser crashed after the game of dice but all data seemed to have saved when reopened the tab, continued as usual. Lost participant attention for the last two-ish minutes of short ANT but he continued to do the task. | J17: Y | M17: 45108 | N17: Tanriverdi/King | O17: Did very well, we had to let him go to the bathroom after he finished PAT, so it delayed the completion a bit (finished in 1 hr 50 mins), and we had to rerun Scout & localizer before planet GNG. | P17: Y | Q17: Y | R17: Y | U17: 45740 | V17: Danny | X17: Great Visit - Great Kid | AC17: 45743 | AD17: Avi | AE17: Danny | AH17: Good session, no notes | AI17: Y | AJ17: Y | AK17: Y
A18: 132 | B18: {=IFNA(XLOOKUP(A18,'New Signups'!C:C,'New Signups'!D:D),"-")} -> Joshua | C18: {=IFNA(XLOOKUP(A18,'New Signups'!C:C,'New Signups'!E:E),"-")} -> Gerecht | D18: 1014 | E18: 1 | F18: 1 | G18: 45131 | H18: Wyatt | I18: Game of Dice, UberBall and Short Ans. not complete | J18: Y | M18: 45145 | N18: Murray/King | O18: was fidgety and struggles with a lot of the tasks. Pat Task practice would not load. Missed a lot of the pat task trails. We did not get to DTI. | P18: Y | Q18: Y | R18: Y | U18: 45732 | V18: Avi | X18: His objective screen time data should be ignored (he said that its innaccurate and shows him being on it all night when he hasn't been) | Y18: Y | Z18: Y | AC18: 45762 | AD18: Danny | AH18: No notes- understood GNG but was just really bad at it | AI18: Y | AJ18: Y | AK18: Y
A19: 133 | B19: {=IFNA(XLOOKUP(A19,'New Signups'!C:C,'New Signups'!D:D),"-")} -> JJ (Jensen) | C19: {=IFNA(XLOOKUP(A19,'New Signups'!C:C,'New Signups'!E:E),"-")} -> Cressman | D19: 1008 | E19: 1 | F19: 1 | G19: 45090 | H19: Murray | I19: Bored after first break, got easily distracted and would tell personal anecdotes. said the games are boring - did not run peer social feedback task, was told not to run. Should do at visit two | J19: Y | M19: 45100 | N19: Tanriverdi/Foley/King | O19: Did very well, got tired toward the end but completed all tasks. Went into the scanner a little late, finished at around 2h30m. Planet GNG may have issues (more in REDCap). | P19: Y | Q19: Y | R19: Y | U19: 45737 | V19: Brooke | X19: PAT friends task slightly glitched, great visit | Y19: Y | Z19: Y | AC19: 45779 | AD19: Avi | AE19: Danny | AH19: He left the scanner after the second round of GnG. The movie was playing in the background for the whole GnG. | AI19: Y | AJ19: Y | AK19: Y
A20: 136 | B20: Holden | C20: Saalbach | D20: 1010 | E20: 1 | G20: 45103 | H20: Wyatt | I20: Bored often and got very easily distracted. Got very upset during dice when money was lost. Participant had difficulty remaining focused during tasks and surveys most during ANT. | J20: Y | M20: 45105 | N20: King/Murray | O20: He could not handle the mri. We won't be able to follow up with him. | Q20: Y | R20: Y
A21: 153 | B21: {=IFNA(XLOOKUP(A21,'New Signups'!C:C,'New Signups'!D:D),"-")} -> Idris | C21: {=IFNA(XLOOKUP(A21,'New Signups'!C:C,'New Signups'!E:E),"-")} -> Taylor | D21: 1004 | E21: 1 | F21: 1 | G21: 45113 | H21: Murray | I21: For stoplight I accidentally put in 1003 as his PID. I was able to backup the stoplight files to OneDrive. His correct stoplight files are in his folder 1004 in the stoplight folder. The output files include 1003 in the name due to my error, however I was able to differenciate based on the date of the output files. Aside from incorrect labling of files in the folder and on Toad in 841 all data is there and backed up on the OneDrive as it typically would be. 1003 is also in redcap for stoplight which needs to be changed if possible. other than that great visit, but he completed all the surveys and games in just an hour. | J21: Y | M21: 45121 | N21: King/Murray | O21: P pressed squeeze ball because it was too loud and his ears hurt. We took him out of scanner to readjust. When we did that and put him back in we got an error on the scanning computer. Tried to make adjustments to P's placement in scanner etc. Took P in and out 3 or 4 times and continued to get the same system error. Only got through PAT block one. P is willing to come back and is scheduled for the 27th of July, however it is rather far away and does not follow protocol so we are reaching out to Jason to get his approval/denial. P was very understanding and so was the mom. P did seem to be a little stressed but did not verbalize if this was in fact the case or not. (assumption he was stressed). | P21: - | Q21: - | R21: Y
A22: 155 | B22: {=IFNA(XLOOKUP(A22,'New Signups'!C:C,'New Signups'!D:D),"-")} -> Jacob | C22: {=IFNA(XLOOKUP(A22,'New Signups'!C:C,'New Signups'!E:E),"-")} -> Gibbons | D22: 1015 | E22: 1 | F22: 1 | G22: 45161 | H22: Shulski | I22: UberBall and Short Ans. not complete | J22: Y | M22: 45194 | N22: King | O22: good session, got bored during gng but did his best | P22: Y | Q22: Y | R22: Y | U22: 45739 | V22: Avi | X22: Game of Dice couldn't be run due to a lack of disk space on the 844 computer | Y22: Couldn't transfer the data because the computer was full. | Z22: Y | AC22: 45810 | AD22: Avi | AE22: Kirsten | AF22: Binh | AH22: video sound was playing in gng but otherwise all's good | AI22: Y | AJ22: Y | AK22: Y
A23: 160 | B23: Kiran | C23: Singh | D23: 1013 | E23: 1 | G23: 45114 | H23: King | I23: Great session, finished all tasks on time. great P!! | J23: Y
A24: 169 | B24: {=IFNA(XLOOKUP(A24,'New Signups'!C:C,'New Signups'!D:D),"-")} -> Magnolia (Maggie) | C24: {=IFNA(XLOOKUP(A24,'New Signups'!C:C,'New Signups'!E:E),"-")} -> Becker | D24: 1012 | E24: 1 | F24: 1 | G24: 45160 | H24: Murray | I24: Good session | J24: Y | M24: 45163 | N24: Murray/King | O24: She did great, no notes | P24: Y | Q24: Y | R24: Y | U24: 45741 | AC24: 45741
A25: 180 | B25: {=IFNA(XLOOKUP(A25,'New Signups'!C:C,'New Signups'!D:D),"-")} -> Connor | C25: {=IFNA(XLOOKUP(A25,'New Signups'!C:C,'New Signups'!E:E),"-")} -> Fitzpatrick | D25: 1016 | E25: 1 | F25: 1 | G25: 45192 | H25: King | I25: gender fluid, uses he/she pronouns | J25: Y | M25: 10/1/2023 | N25: King | O25: He did great, no notes | P25: Y | Q25: Y | R25: Y | U25: 45851 | V25: Megan | X25: No notes, good session | Y25: Y | Z25: Y | AC25: 45858 | AD25: Avi | AE25: Lina | AF25: Ife | AH25: No Notes (some internal self-tests and calibrations were skipped for PAT) | AJ25: Y | AK25: Y
A26: 339 | B26: {=IFNA(XLOOKUP(A26,'New Signups'!C:C,'New Signups'!D:D),"-")} -> Colton | C26: {=IFNA(XLOOKUP(A26,'New Signups'!C:C,'New Signups'!E:E),"-")} -> Tekimang | D26: 1021 | E26: 1 | F26: 1 | G26: 45263 | H26: Zweben | I26: good session | J26: Y | M26: 45270 | N26: Murray/Zweben | O26: Could not get through foraging. Moved A LOT with countless reminders not to move. When taking him out of the scanner his head was longer up against the cushions, and his shoulders were not touching the head coil like they should. | P26: Y | Q26: Y | R26: Y | U26: 45762 | V26: Samra | X26: No notes, good session | Y26: Y | Z26: Y | AC26: 45765 | AD26: Avi | AE26: Brooke | AH26: He had a headache and wanted to leave. Skipped GNG and DTI | AI26: Y | AJ26: Y | AK26: Y
A27: 393 | B27: {=IFNA(XLOOKUP(A27,'New Signups'!C:C,'New Signups'!D:D),"-")} -> Hai-Dinh | C27: {=IFNA(XLOOKUP(A27,'New Signups'!C:C,'New Signups'!E:E),"-")} -> Ballock | D27: 1019 | E27: 1 | F27: 1 | G27: 45248 | H27: Murray | I27: great Participant definately took the time to understand the survey and provide us with a thoughtful response.Did not like how long the surveys were, and was very concerned when the survey would "skip" parts of the survey based one of his prior answers (i.e. doesn't own a smartphone). Very inquisitive | J27: Y | M27: 45304 | N27: Murray/Zweben | O27: Good scan no issues easy kid, smart and quiet | P27: Y | Q27: Y | R27: Y | U27: 45833 | V27: Andrew | X27: no notes good session | Y27: y | Z27: y | AC27: 45854 | AD27: Avi | AE27: Kirsten | AF27: Lina | AG27: Ife | AH27: He got up before GNG; we ran the short T1 (some internal self-tests and calibrations were skipped for PAT) | AJ27: Y | AK27: Y
A28: 395 | B28: {=IFNA(XLOOKUP(A28,'New Signups'!C:C,'New Signups'!D:D),"-")} -> Amaya | C28: {=IFNA(XLOOKUP(A28,'New Signups'!C:C,'New Signups'!E:E),"-")} -> Mestre | D28: 1020 | E28: 1 | F28: 1 | G28: 45258 | H28: Murray | I28: ANT was a complete disaster, she would just click to click, missed a TON of trials, ran out of the room in the middle of the task but came right back (missed about 4 trials in her tome away from computer). Kept wanting to walk around or see her mom, but all of the servey and the games were completed | J28: Y | M28: 45272 | N28: Murray | O28: ONLY BEHAVIORAL | P28: NA | Q28: Y | R28: Y | AC28: 45777 | AD28: Avi | AE28: Jay | AH28: V2 happened before the V1 | AI28: Y | AJ28: Y | AK28: Y
A29: 507 | B29: {=IFNA(XLOOKUP(A29,'New Signups'!C:C,'New Signups'!D:D),"-")} -> Nashali | C29: {=IFNA(XLOOKUP(A29,'New Signups'!C:C,'New Signups'!E:E),"-")} -> Ortiz-Rivera | D29: 1022 | E29: 1 | F29: 1 | G29: 45318 | H29: Jay | I29: obtain screen time data in V2 | J29: Y | M29: 45092 | N29: Murray/Zweben | O29: Had to run localizer/field maps again before GNG (otherwise good scan) | P29: Y | Q29: Y | R29: Y | U29: 45970 | V29: Rae | X29: Spotlight froze when exiting the game. good session | Y29: Y | Z29: Y | AC29: 45970 | AD29: Kirsten | AE29: Megan | AF29: Rae | AG29: Avi | AH29: fell asleep - couldnt run much (just got PAT and DD alone) | AI29: y | AJ29: Y | AK29: Y
A30: 508 | B30: {=IFNA(XLOOKUP(A30,'New Signups'!C:C,'New Signups'!D:D),"-")} -> Anthony | C30: {=IFNA(XLOOKUP(A30,'New Signups'!C:C,'New Signups'!E:E),"-")} -> Ortiz-Rivera Jr | D30: 1023 | E30: 1 | F30: 1 | G30: 45318 | H30: Zweben | I30: good session, good kid | J30: Y | M30: 45319 | N30: Murray/Zweben | O30: First round of go-no-go was pressing the yellow button instead of the blue button. Used the correct button for the folowing 3 blocks. | P30: Y | Q30: Y | R30: Y | U30: 45765 | V30: Avi | W30: Aashna | X30: No notes, good session | Y30: Y | Z30: Y | AC30: 45949 | AD30: Isabel | AE30: Kirsten | AH30: Had to take participant out to readjust glasses (still had trouble reading all of the hobbies) and rerun short T1. Participant key presses registering on MATLAB, but not registering on the game screen for PAT 1 (likely unusable). Fixed for PAT round 2! Had to skip GnG for time reasons (Participant 30 minutes late) but did do DTI | AI30: Y | AJ30: Y | AK30: Y
A31: 509 | B31: {=IFNA(XLOOKUP(A31,'New Signups'!C:C,'New Signups'!D:D),"-")} -> Noemi | C31: {=IFNA(XLOOKUP(A31,'New Signups'!C:C,'New Signups'!E:E),"-")} -> Ortiz-Rivera | D31: 1024 | E31: 1 | F31: 1 | G31: 45318 | H31: Murray | I31: Good kid, did not have phoen with her to fill out that section of the survey | J31: Y | M31: 45338 | N31: Zweben/Riya | O31: GNG crashed and ould not run | P31: Y | Q31: Y | R31: Y | U31: 45765 | V31: Danny | X31: No notes, good session | Y31: Y | Z31: Y | AC31: 45935 | AD31: Kirsten | AE31: Megan | AH31: Psychopy crashed in the middle of the first gng round - skipped it and didnt dd social because it still is not working
A32: 510 | B32: {=IFNA(XLOOKUP(A32,'New Signups'!C:C,'New Signups'!D:D),"-")} -> Amina | C32: {=IFNA(XLOOKUP(A32,'New Signups'!C:C,'New Signups'!E:E),"-")} -> Ortiz-Rivera | D32: 1025 | E32: 1 | F32: 1 | G32: 45318 | H32: Murray | I32: good session, good kid | J32: Y | M32: 45338 | N32: Murray/Vince | O32: no notes good session | P32: Y | Q32: Y | R32: Y | U32: 45765 | V32: Danny | X32: No notes, good session | Y32: Y | Z32: Y | AC32: 45935 | AD32: Kirsten | AE32: Megan | AH32: started PAT 5 seconds left of first scan - did three participants and then stated second scan... took break midway of 1st gng session (did not look like she understood gng - low points even after explained twice) - cut dd social (confrmity task isnt working and time restrain) ran last field maps with movie
